Workbook
Name o_status: Orders!$H$2:$H$1501
Name o_reason: Orders!$T$2:$T$1501
Name o_order_id: Orders!$A$2:$A$1501
Name o_promised_eta: Orders!$P$2:$P$1501
Name o_actual_min: Orders!$Q$2:$Q$1501
Name o_delay: Orders!$R$2:$R$1501
Name c_id: Calc_Orders!$A$5:$A$1504
Name c_store: Calc_Orders!$B$5:$B$1504
Name c_cust: Calc_Orders!$C$5:$C$1504
Name c_status: Calc_Orders!$D$5:$D$1504
Name c_deliv: Calc_Orders!$E$5:$E$1504
Name c_delay: Calc_Orders!$F$5:$F$1504
Name c_late: Calc_Orders!$G$5:$G$1504
Name c_sev: Calc_Orders!$H$5:$H$1504
Name c_cancel: Calc_Orders!$I$5:$I$1504
Name c_elig: Calc_Orders!$J$5:$J$1504
Name c_group: Calc_Orders!$K$5:$K$1504
Name c_peak: Calc_Orders!$L$5:$L$1504
Name c_peakok: Calc_Orders!$M$5:$M$1504
Name c_rain: Calc_Orders!$N$5:$N$1504
Name c_date: Calc_Orders!$O$5:$O$1504
Name c_hour: Calc_Orders!$P$5:$P$1504
Name c_dmatch: Calc_Orders!$Q$5:$Q$1504
Name c_dorders: Calc_Orders!$R$5:$R$1504
Name c_typ: Calc_Orders!$S$5:$S$1504
Name c_load: Calc_Orders!$T$5:$T$1504
Name c_loadd: Calc_Orders!$U$5:$U$1504
Name c_loadop: Calc_Orders!$V$5:$V$1504
Name c_qall: Calc_Orders!$W$5:$W$1504
Name c_qop: Calc_Orders!$X$5:$X$1504
Name c_pickstore: Calc_Orders!$Y$5:$Y$1504
Name c_slow: Calc_Orders!$Z$5:$Z$1504
Name c_age: Calc_Orders!$AA$5:$AA$1504
Name c_new: Calc_Orders!$AB$5:$AB$1504
Name c_veh: Calc_Orders!$AC$5:$AC$1504
Name c_exp: Calc_Orders!$AD$5:$AD$1504
Name c_homematch: Calc_Orders!$AE$5:$AE$1504
Name c_dist: Calc_Orders!$AF$5:$AF$1504
Name c_prom: Calc_Orders!$AG$5:$AG$1504
Name c_act: Calc_Orders!$AH$5:$AH$1504
Name c_pick: Calc_Orders!$AI$5:$AI$1504
Name c_wait: Calc_Orders!$AJ$5:$AJ$1504
Name c_trav: Calc_Orders!$AK$5:$AK$1504
Name c_sum01: Calc_Orders!$AL$5:$AL$1504
Name c_shp: Calc_Orders!$AM$5:$AM$1504
Name c_shw: Calc_Orders!$AN$5:$AN$1504
Name c_sht: Calc_Orders!$AO$5:$AO$1504
Name c_traf: Calc_Orders!$AP$5:$AP$1504
Name c_event: Calc_Orders!$AQ$5:$AQ$1504
Name c_wpk: Calc_Orders!$AR$5:$AR$1504
Name c_wop: Calc_Orders!$AS$5:$AS$1504
Name c_ppk: Calc_Orders!$AT$5:$AT$1504
Name c_pop: Calc_Orders!$AU$5:$AU$1504
Name c_prpk: Calc_Orders!$AV$5:$AV$1504
Name c_prop: Calc_Orders!$AW$5:$AW$1504
Name c_acpk: Calc_Orders!$AX$5:$AX$1504
Name c_acop: Calc_Orders!$AY$5:$AY$1504
Name c_latedelay: Calc_Orders!$AZ$5:$AZ$1504
Name c_ldpk: Calc_Orders!$BA$5:$BA$1504
Name c_ldop: Calc_Orders!$BB$5:$BB$1504

Sheet Orders
A1: order_id | B1: customer_id | C1: store_id | D1: rider_id | E1: placed_at | F1: promised_delivery_at | G1: actual_delivery_at | H1: order_status | I1: basket_size | J1: item_count | K1: order_value_inr | L1: distance_km | M1: picking_time_min_est | N1: rider_wait_time_min_est | O1: travel_time_min_est | P1: promised_eta_min | Q1: actual_delivery_duration_min | R1: delay_min | S1: on_time_flag | T1: cancellation_reason | U1: order_hour | V1: is_peak_hour | W1: rain_condition | X1: event_day | Y1: traffic_congestion_index
A2: O00001 | B2: C0113 | C2: S010 | D2: R003 | E2: 46279.483 | F2: 46279.491 | G2: 46279.497 | H2: Delivered | I2: 1 | J2: 5 | K2: 947.37 | L2: 0.8 | M2: 7.1 | N2: 7.6 | O2: 5 | P2: 10.7 | Q2: 19.7 | R2: 9 | S2: FALSE | U2: 11 | V2: FALSE | W2: Heavy | X2: FALSE | Y2: 0.36
A3: O00002 | B3: C0091 | C3: S008 | D3: R040 | E3: 46274.769 | F3: 46274.777 | G3: 46274.776 | H3: Delivered | I3: 5 | J3: 9 | K3: 950.19 | L3: 2.77 | M3: 2.3 | N3: 4 | O3: 4.2 | P3: 11.5 | Q3: 10.5 | R3: -1 | S3: TRUE | U3: 18 | V3: FALSE | X3: FALSE | Y3: 0.63
A4: O00003 | B4: C0085 | C4: S003 | D4: R033 | E4: 46272.717 | F4: 46272.724 | G4: 46272.723 | H4: Delivered | I4: 4 | J4: 7 | K4: 343.25 | L4: 2.1 | M4: 2.9 | N4: 2.4 | O4: 4 | P4: 10.2 | Q4: 9.3 | R4: -0.9 | S4: TRUE | U4: 17 | V4: FALSE | X4: TRUE | Y4: 0.54
A5: O00004 | B5: C0159 | C5: S017 | D5: R048 | E5: 46276.785 | F5: 46276.794 | G5: 46276.795 | H5: Delivered | I5: 5 | J5: 5 | K5: 908.19 | L5: 2.63 | M5: 3.2 | N5: 5.3 | O5: 5.6 | P5: 12.2 | Q5: 14.2 | R5: 2 | S5: FALSE | U5: 18 | V5: FALSE | X5: FALSE | Y5: 0.33
A6: O00005 | B6: C0138 | C6: S012 | D6: R003 | E6: 46267.658 | F6: 46267.665 | G6: 46267.664 | H6: Delivered | I6: 1 | J6: 6 | K6: 1441.28 | L6: 4.18 | M6: 2.9 | N6: 1.6 | O6: 4.7 | P6: 10.4 | Q6: 9.2 | R6: -1.2 | S6: TRUE | U6: 15 | V6: FALSE | X6: FALSE | Y6: 0.44
A7: O00006 | B7: C0085 | C7: S003 | D7: R028 | E7: 46276.996 | F7: 46277.003 | G7: 46277.003 | H7: Delivered | I7: 5 | J7: 10 | K7: 904.36 | L7: 1.99 | M7: 2.7 | N7: 4 | O7: 3.9 | P7: 10.9 | Q7: 10.6 | R7: -0.3 | S7: TRUE | U7: 23 | V7: FALSE | X7: FALSE | Y7: 0.59
A8: O00007 | B8: C0072 | C8: S011 | D8: R044 | E8: 46274.403 | F8: 46274.411 | G8: 46274.41 | H8: Delivered | I8: 5 | J8: 11 | K8: 322.36 | L8: 1.61 | M8: 3.9 | N8: 3.7 | O8: 2.3 | P8: 10.7 | Q8: 9.9 | R8: -0.8 | S8: TRUE | U8: 9 | V8: FALSE | X8: FALSE | Y8: 0.38
A9: O00008 | B9: C0171 | C9: S009 | D9: R039 | E9: 46278.914 | F9: 46278.921 | G9: 46278.92 | H9: Delivered | I9: 4 | J9: 5 | K9: 499.35 | L9: 0.5 | M9: 1.5 | N9: 5.8 | O9: 1.7 | P9: 9.7 | Q9: 9 | R9: -0.7 | S9: TRUE | U9: 21 | V9: TRUE | X9: FALSE | Y9: 0.48
A10: O00009 | B10: C0053 | C10: S007 | D10: R044 | E10: 46276.42 | F10: 46276.428 | G10: 46276.427 | H10: Delivered | I10: 5 | J10: 6 | K10: 1383.14 | L10: 1.07 | M10: 3.3 | N10: 4.1 | O10: 3.2 | P10: 10.8 | Q10: 10.6 | R10: -0.2 | S10: TRUE | U10: 10 | V10: FALSE | X10: FALSE | Y10: 0.52
A11: O00010 | B11: C0122 | C11: S005 | D11: R041 | E11: 46279.962 | F11: 46279.969 | G11: 46279.969 | H11: Delivered | I11: 2 | J11: 12 | K11: 1595.36 | L11: 1.86 | M11: 3.4 | N11: 3.7 | O11: 3.3 | P11: 11 | Q11: 10.4 | R11: -0.6 | S11: TRUE | U11: 23 | V11: FALSE | W11: Light | X11: FALSE | Y11: 0.44
A12: O00011 | B12: C0133 | C12: S003 | D12: R046 | E12: 46270.522 | F12: 46270.528 | G12: 46270.528 | H12: Delivered | I12: 2 | J12: 6 | K12: 1248.7 | L12: 1.3 | M12: 2.4 | N12: 3.1 | O12: 2.6 | P12: 8.5 | Q12: 8.1 | R12: -0.4 | S12: TRUE | U12: 12 | V12: FALSE | X12: FALSE | Y12: 0.77
A13: O00012 | B13: C0106 | C13: S015 | D13: R067 | E13: 46266.653 | F13: 46266.659 | G13: 46266.659 | H13: Delivered | I13: 5 | J13: 8 | K13: 731.09 | L13: 0.68 | M13: 4 | N13: 3.6 | O13: 1.8 | P13: 9.6 | Q13: 9.4 | R13: -0.2 | S13: TRUE | U13: 15 | V13: FALSE | X13: FALSE | Y13: 0.14
A14: O00013 | B14: C0173 | C14: S012 | D14: R021 | E14: 46274.485 | F14: 46274.492 | G14: 46274.492 | H14: Delivered | I14: 3 | J14: 5 | K14: 500.07 | L14: 5.25 | M14: 2.6 | N14: 1.2 | O14: 5.3 | P14: 9.8 | Q14: 9.1 | R14: -0.7 | S14: TRUE | U14: 11 | V14: FALSE | W14: Heavy | X14: FALSE | Y14: 0.31
A15: O00014 | B15: C0216 | C15: S011 | D15: R038 | E15: 46277.356 | F15: 46277.363 | G15: 46277.363 | H15: Delivered | I15: 1 | J15: 10 | K15: 1122.83 | L15: 1.52 | M15: 3.1 | N15: 4.3 | O15: 2.6 | P15: 10.9 | Q15: 10 | R15: -0.9 | S15: TRUE | U15: 8 | V15: FALSE | X15: FALSE | Y15: 0.57
A16: O00015 | B16: C0170 | C16: S004 | D16: R011 | E16: 46273.564 | F16: 46273.57 | G16: 46273.57 | H16: Delivered | I16: 3 | J16: 5 | K16: 1284.14 | L16: 1.74 | M16: 1.3 | N16: 1.1 | O16: 6.9 | P16: 9.3 | Q16: 9.3 | R16: 0 | S16: TRUE | U16: 13 | V16: FALSE | W16: Heavy | X16: FALSE | Y16: 0.26
A17: O00016 | B17: C0127 | C17: S015 | D17: R003 | E17: 46269.68 | F17: 46269.688 | G17: 46269.687 | H17: Delivered | I17: 3 | J17: 6 | K17: 871.11 | L17: 2.61 | M17: 3.3 | N17: 2.7 | O17: 4.2 | P17: 11.1 | Q17: 10.2 | R17: -0.9 | S17: TRUE | U17: 16 | V17: FALSE | X17: FALSE | Y17: 0.22
A18: O00017 | B18: C0210 | C18: S019 | D18: R064 | E18: 46278.457 | F18: 46278.463 | G18: 46278.463 | H18: Delivered | I18: 3 | J18: 11 | K18: 317.7 | L18: 2.15 | M18: 3.8 | N18: 2 | O18: 3.1 | P18: 9.4 | Q18: 8.9 | R18: -0.5 | S18: TRUE | U18: 10 | V18: FALSE | X18: FALSE | Y18: 0.44
A19: O00018 | B19: C0092 | C19: S012 | D19: R021 | E19: 46271.672 | F19: 46271.679 | G19: 46271.678 | H19: Delivered | I19: 3 | J19: 15 | K19: 607.45 | L19: 4.52 | M19: 3.1 | N19: 1.7 | O19: 5.2 | P19: 11.1 | Q19: 10 | R19: -1.1 | S19: TRUE | U19: 16 | V19: FALSE | W19: Light | X19: FALSE | Y19: 0.22
A20: O00019 | B20: C0101 | C20: S003 | D20: R016 | E20: 46274.434 | F20: 46274.441 | G20: 46274.441 | H20: Delivered | I20: 3 | J20: 6 | K20: 525.46 | L20: 2.09 | M20: 3.8 | N20: 2.2 | O20: 3.5 | P20: 10.2 | Q20: 9.5 | R20: -0.7 | S20: TRUE | U20: 10 | V20: FALSE | X20: FALSE | Y20: 0.31
A21: O00020 | B21: C0208 | C21: S017 | D21: R020 | E21: 46275.982 | F21: 46275.989 | G21: 46275.989 | H21: Delivered | I21: 2 | J21: 7 | K21: 1336.97 | L21: 1.34 | M21: 2.7 | N21: 4.6 | O21: 2.4 | P21: 10.5 | Q21: 9.7 | R21: -0.8 | S21: TRUE | U21: 23 | V21: FALSE | X21: FALSE | Y21: 0.35
A22: O00021 | B22: C0073 | C22: S003 | D22: R006 | E22: 46268.641 | F22: 46268.65 | G22: 46268.649 | H22: Delivered | I22: 6 | J22: 6 | K22: 674.26 | L22: 2.1 | M22: 2.7 | N22: 4.8 | O22: 3.9 | P22: 12.4 | Q22: 11.4 | R22: -1 | S22: TRUE | U22: 15 | V22: FALSE | X22: FALSE | Y22: 0.51
A23: O00022 | B23: C0173 | C23: S012 | D23: R070 | E23: 46279.917 | F23: 46279.925 | G23: 46279.924 | H23: Delivered | I23: 5 | J23: 10 | K23: 1648.63 | L23: 1.45 | M23: 4.3 | N23: 3.9 | O23: 2.6 | P23: 11.4 | Q23: 10.8 | R23: -0.6 | S23: TRUE | U23: 22 | V23: FALSE | W23: Light | X23: FALSE | Y23: 0.29
A24: O00023 | B24: C0070 | C24: S020 | D24: R026 | E24: 46274.967 | F24: 46274.974 | G24: 46274.978 | H24: Delivered | I24: 3 | J24: 7 | K24: 906.38 | L24: 2.35 | M24: 6.6 | N24: 3.7 | O24: 6.4 | P24: 10.7 | Q24: 16.8 | R24: 6.1 | S24: FALSE | U24: 23 | V24: FALSE | X24: FALSE | Y24: 0.68
A25: O00024 | B25: C0034 | C25: S002 | D25: R039 | E25: 46273.882 | F25: 46273.889 | G25: 46273.891 | H25: Delivered | I25: 2 | J25: 5 | K25: 848.05 | L25: 0.5 | M25: 3.2 | N25: 7.7 | O25: 2 | P25: 10.6 | Q25: 12.9 | R25: 2.3 | S25: FALSE | U25: 21 | V25: TRUE | X25: FALSE | Y25: 0.32
A26: O00025 | B26: C0141 | C26: S009 | D26: R048 | E26: 46268.605 | F26: 46268.612 | G26: 46268.614 | H26: Delivered | I26: 2 | J26: 6 | K26: 1361.45 | L26: 2.44 | M26: 2.5 | N26: 5.6 | O26: 5.7 | P26: 9.8 | Q26: 13.8 | R26: 4 | S26: FALSE | U26: 14 | V26: FALSE | X26: FALSE | Y26: 0.51
A27: O00026 | B27: C0172 | C27: S003 | D27: R045 | E27: 46271.781 | F27: 46271.788 | G27: 46271.787 | H27: Delivered | I27: 4 | J27: 11 | K27: 922.47 | L27: 1.72 | M27: 3.3 | N27: 0.7 | O27: 4.3 | P27: 9.3 | Q27: 8.3 | R27: -1 | S27: TRUE | U27: 18 | V27: FALSE | W27: Light | X27: FALSE | Y27: 0.69
A28: O00027 | B28: C0157 | C28: S007 | D28: R077 | E28: 46278.715 | F28: 46278.723 | G28: 46278.722 | H28: Delivered | I28: 5 | J28: 6 | K28: 1123.31 | L28: 0.85 | M28: 4.6 | N28: 4.3 | O28: 2.1 | P28: 12.6 | Q28: 11 | R28: -1.6 | S28: TRUE | U28: 17 | V28: FALSE | X28: FALSE | Y28: 0.19
A29: O00028 | B29: C0050 | C29: S001 | D29: R067 | E29: 46276.477 | F29: 46276.484 | G29: 46276.484 | H29: Delivered | I29: 6 | J29: 11 | K29: 1549.03 | L29: 1.12 | M29: 4.8 | N29: 1.4 | O29: 3.6 | P29: 10.2 | Q29: 9.8 | R29: -0.4 | S29: TRUE | U29: 11 | V29: FALSE | X29: FALSE | Y29: 0.51
A30: O00029 | B30: C0160 | C30: S016 | D30: R019 | E30: 46269.489 | F30: 46269.497 | G30: 46269.497 | H30: Delivered | I30: 2 | J30: 4 | K30: 1251.96 | L30: 0.91 | M30: 7.3 | N30: 1.2 | O30: 2.7 | P30: 11.5 | Q30: 11.2 | R30: -0.3 | S30: TRUE | U30: 11 | V30: FALSE | X30: FALSE | Y30: 0.4
A31: O00030 | B31: C0115 | C31: S019 | D31: R006 | E31: 46279.392 | F31: 46279.4 | G31: 46279.402 | H31: Delivered | I31: 2 | J31: 2 | K31: 1536.48 | L31: 0.75 | M31: 4 | N31: 6.4 | O31: 3.8 | P31: 10.8 | Q31: 14.3 | R31: 3.5 | S31: FALSE | U31: 9 | V31: FALSE | W31: Light | X31: FALSE | Y31: 0.42
A32: O00031 | B32: C0107 | C32: S016 | D32: R058 | E32: 46272.708 | F32: 46272.716 | G32: 46272.716 | H32: Delivered | I32: 4 | J32: 7 | K32: 1300.65 | L32: 1.66 | M32: 3.7 | N32: 3.1 | O32: 3.6 | P32: 10.8 | Q32: 10.4 | R32: -0.4 | S32: TRUE | U32: 17 | V32: FALSE | W32: Light | X32: FALSE | Y32: 0.3
A33: O00032 | B33: C0048 | C33: S002 | D33: R044 | E33: 46267.875 | F33: 46267.882 | G33: 46267.882 | H33: Delivered | I33: 3 | J33: 4 | K33: 1355.56 | L33: 1.17 | M33: 1.4 | N33: 5.1 | O33: 2.9 | P33: 9.9 | Q33: 9.4 | R33: -0.5 | S33: TRUE | U33: 21 | V33: TRUE | X33: FALSE | Y33: 0.6
A34: O00033 | B34: C0006 | C34: S005 | D34: R054 | E34: 46279.79 | F34: 46279.798 | G34: 46279.798 | H34: Delivered | I34: 4 | J34: 4 | K34: 807.5 | L34: 2.62 | M34: 2.7 | N34: 4.2 | O34: 4.1 | P34: 11.7 | Q34: 11 | R34: -0.7 | S34: TRUE | U34: 18 | V34: FALSE | X34: FALSE | Y34: 0.27
A35: O00034 | B35: C0126 | C35: S018 | D35: R021 | E35: 46269.374 | F35: 46269.38 | G35: 46269.38 | H35: Delivered | I35: 3 | J35: 7 | K35: 1553.14 | L35: 2.18 | M35: 3.3 | N35: 2.5 | O35: 3.4 | P35: 9.6 | Q35: 9.2 | R35: -0.4 | S35: TRUE | U35: 8 | V35: FALSE | X35: FALSE | Y35: 0.42
A36: O00035 | B36: C0154 | C36: S005 | D36: R030 | E36: 46269.549 | F36: 46269.557 | G36: 46269.556 | H36: Delivered | I36: 1 | J36: 8 | K36: 883.76 | L36: 1.82 | M36: 3.4 | N36: 0 | O36: 6.8 | P36: 10.6 | Q36: 10.2 | R36: -0.4 | S36: TRUE | U36: 13 | V36: FALSE | W36: Heavy | X36: FALSE | Y36: 0.97
A37: O00036 | B37: C0246 | C37: S001 | D37: R059 | E37: 46269.549 | F37: 46269.556 | G37: 46269.558 | H37: Delivered | I37: 5 | J37: 10 | K37: 511.05 | L37: 1.67 | M37: 3.9 | N37: 2.9 | O37: 5.2 | P37: 9.3 | Q37: 11.9 | R37: 2.6 | S37: FALSE | U37: 13 | V37: FALSE | X37: FALSE | Y37: 0.39
A38: O00037 | B38: C0109 | C38: S016 | E38: 46272.425 | F38: 46272.432 | H38: Cancelled | I38: 3 | J38: 3 | K38: 390.18 | L38: 2.6 | M38: 5.1 | N38: 1.4 | O38: 7.2 | P38: 10.4 | T38: Rider unavailable | U38: 10 | V38: FALSE | W38: Heavy | X38: FALSE | Y38: 0.09
A39: O00038 | B39: C0204 | C39: S016 | D39: R063 | E39: 46270.881 | F39: 46270.887 | G39: 46270.887 | H39: Delivered | I39: 1 | J39: 7 | K39: 1720.92 | L39: 2.6 | M39: 2.4 | N39: 2.4 | O39: 2.8 | P39: 8.4 | Q39: 7.6 | R39: -0.8 | S39: TRUE | U39: 21 | V39: TRUE | X39: FALSE | Y39: 0.85
A40: O00039 | B40: C0076 | C40: S014 | D40: R072 | E40: 46267.908 | F40: 46267.914 | G40: 46267.924 | H40: Delivered | I40: 3 | J40: 4 | K40: 960.9 | L40: 1.67 | M40: 6.6 | N40: 10.7 | O40: 6.1 | P40: 9.7 | Q40: 23.4 | R40: 13.7 | S40: FALSE | U40: 21 | V40: TRUE | X40: FALSE | Y40: 0.81
...

Sheet Stores
A1: store_id | B1: city | C1: store_age_days | D1: staffing_per_shift | E1: item_availability_pct | F1: avg_picking_time_min | G1: typical_orders_per_hour | H1: service_radius_km | I1: delivered_orders | J1: avg_actual_delivery_duration_min | K1: late_orders | L1: on_time_rate_pct
A2: S001 | B2: Bengaluru | C2: 362 | D2: 6 | E2: 0.927 | F2: 4.59 | G2: 16 | H2: 4.3 | I2: 64 | J2: 10.82 | K2: 11 | L2: 82.8
A3: S002 | B3: Hyderabad | C3: 470 | D3: 9 | E3: 0.981 | F3: 2.39 | G3: 33 | H3: 5 | I3: 80 | J3: 11.1 | K3: 21 | L3: 73.8
A4: S003 | B4: Mumbai | C4: 426 | D4: 11 | E4: 0.962 | F4: 3.84 | G4: 41 | H4: 2.1 | I4: 83 | J4: 10.69 | K4: 20 | L4: 75.9
A5: S004 | B5: Pune | C5: 850 | D5: 9 | E5: 0.949 | F5: 2.19 | G5: 42 | H5: 3.3 | I5: 70 | J5: 10.36 | K5: 11 | L5: 84.3
A6: S005 | B6: Delhi | C6: 138 | D6: 7 | E6: 0.9 | F6: 4.89 | G6: 14 | H6: 4.9 | I6: 76 | J6: 12.11 | K6: 23 | L6: 69.7
A7: S006 | B7: Bengaluru | C7: 412 | D7: 11 | E7: 0.886 | F7: 5.22 | G7: 26 | H7: 4.9 | I7: 58 | J7: 11.68 | K7: 15 | L7: 74.1
A8: S007 | B8: Hyderabad | C8: 661 | D8: 4 | E8: 0.934 | F8: 4.05 | G8: 37 | H8: 4.4 | I8: 88 | J8: 11.49 | K8: 27 | L8: 69.3
A9: S008 | B9: Mumbai | C9: 825 | D9: 8 | E9: 0.981 | F9: 3.46 | G9: 23 | H9: 4.9 | I9: 77 | J9: 12.2 | K9: 25 | L9: 67.5
A10: S009 | B10: Pune | C10: 645 | D10: 5 | E10: 0.905 | F10: 2.66 | G10: 29 | H10: 2.8 | I10: 78 | J10: 10.08 | K10: 11 | L10: 85.9
A11: S010 | B11: Delhi | C11: 744 | D11: 10 | E11: 0.903 | F11: 5.61 | G11: 22 | H11: 4 | I11: 70 | J11: 11.7 | K11: 19 | L11: 72.9
A12: S011 | B12: Bengaluru | C12: 732 | D12: 5 | E12: 0.984 | F12: 5.67 | G12: 31 | H12: 3.3 | I12: 71 | J12: 11.92 | K12: 22 | L12: 69
A13: S012 | B13: Hyderabad | C13: 300 | D13: 7 | E13: 0.891 | F13: 5.23 | G13: 15 | H13: 5.3 | I13: 53 | J13: 11.45 | K13: 13 | L13: 75.5
... A21: S020 | B21: Delhi | C21: 647 | D21: 12 | E21: 0.982 | F21: 5.74 | G21: 15 | H21: 3.8 | I21: 73 | J21: 11.68 | K21: 17 | L21: 76.7

Sheet Riders
A1: rider_id | B1: home_store_id | C1: vehicle_type | D1: experience_months | E1: typical_trips_per_shift | F1: avg_distance_per_trip_km | G1: avg_idle_time_min_per_shift | H1: acceptance_rate_pct | I1: avg_store_wait_time_min
A2: R001 | B2: S015 | C2: EV scooter | D2: 11 | E2: 12 | F2: 2.4 | G2: 44.9 | H2: 0.829 | I2: 4.5
A3: R002 | B3: S016 | C3: EV scooter | D3: 1 | E3: 9 | F3: 3.77 | G3: 39.1 | H3: 0.759 | I3: 7
A4: R003 | B4: S016 | C4: EV scooter | D4: 40 | E4: 5 | F4: 4.1 | G4: 44.1 | H4: 0.797 | I4: 4.2
A5: R004 | B5: S015 | C5: EV scooter | D5: 2 | E5: 10 | F5: 2.94 | G5: 26.6 | H5: 0.74 | I5: 3.2
A6: R005 | B6: S017 | C6: EV scooter | D6: 32 | E6: 13 | F6: 4.99 | G6: 29.7 | H6: 0.83 | I6: 2.9
A7: R006 | B7: S016 | C7: EV scooter | D7: 9 | E7: 12 | F7: 4.9 | G7: 55.8 | H7: 0.834 | I7: 4.8
A8: R007 | B8: S007 | C8: EV scooter | D8: 22 | E8: 11 | F8: 3.61 | G8: 20.4 | H8: 0.762 | I8: 1.7
A9: R008 | B9: S001 | C9: Bicycle | D9: 44 | E9: 17 | F9: 3.84 | G9: 6.6 | H9: 0.822 | I9: 6.1
A10: R009 | B10: S008 | C10: Petrol scooter | D10: 6 | E10: 15 | F10: 5.22 | G10: 26.7 | H10: 0.753 | I10: 1.3
A11: R010 | B11: S005 | C11: EV scooter | D11: 38 | E11: 14 | F11: 1.7 | G11: 32.8 | H11: 0.812 | I11: 8.4
A12: R011 | B12: S018 | C12: EV scooter | D12: 44 | E12: 10 | F12: 3.39 | G12: 64.9 | H12: 0.959 | I12: 2.2
A13: R012 | B13: S008 | C13: Petrol scooter | D13: 37 | E13: 15 | F13: 3.83 | G13: 51.3 | H13: 0.857 | I13: 6.4
... A81: R080 | B81: S009 | C81: Bicycle | D81: 40 | E81: 9 | F81: 2.85 | G81: 49.2 | H81: 0.77 | I81: 1.7

Sheet Demand
A1: store_id | B1: date | C1: hour | D1: day_of_week | E1: orders_placed_in_hour | F1: is_peak_window | G1: rain_condition | H1: event_day
A2: S001 | B2: 46266 | C2: 8 | D2: Tuesday | E2: 10 | F2: FALSE | H2: FALSE
A3: S001 | B3: 46266 | C3: 9 | D3: Tuesday | E3: 6 | F3: FALSE | H3: FALSE
A4: S001 | B4: 46266 | C4: 10 | D4: Tuesday | E4: 16 | F4: FALSE | G4: Heavy | H4: FALSE
A5: S001 | B5: 46266 | C5: 11 | D5: Tuesday | E5: 24 | F5: FALSE | H5: FALSE
A6: S001 | B6: 46266 | C6: 12 | D6: Tuesday | E6: 12 | F6: FALSE | G6: Light | H6: FALSE
A7: S001 | B7: 46266 | C7: 13 | D7: Tuesday | E7: 19 | F7: FALSE | G7: Heavy | H7: FALSE
A8: S001 | B8: 46266 | C8: 14 | D8: Tuesday | E8: 12 | F8: FALSE | G8: Light | H8: FALSE
A9: S001 | B9: 46266 | C9: 15 | D9: Tuesday | E9: 15 | F9: FALSE | G9: Light | H9: FALSE
A10: S001 | B10: 46266 | C10: 16 | D10: Tuesday | E10: 21 | F10: FALSE | G10: Light | H10: FALSE
A11: S001 | B11: 46266 | C11: 17 | D11: Tuesday | E11: 8 | F11: FALSE | H11: FALSE
A12: S001 | B12: 46266 | C12: 18 | D12: Tuesday | E12: 18 | F12: FALSE | G12: Heavy | H12: FALSE
A13: S001 | B13: 46266 | C13: 19 | D13: Tuesday | E13: 32 | F13: TRUE | H13: FALSE
A14: S001 | B14: 46266 | C14: 20 | D14: Tuesday | E14: 24 | F14: TRUE | H14: FALSE
A15: S001 | B15: 46266 | C15: 21 | D15: Tuesday | E15: 15 | F15: TRUE | G15: Heavy | H15: FALSE
A16: S001 | B16: 46266 | C16: 22 | D16: Tuesday | E16: 26 | F16: FALSE | H16: FALSE
A17: S001 | B17: 46266 | C17: 23 | D17: Tuesday | E17: 17 | F17: FALSE | H17: FALSE
A18: S002 | B18: 46266 | C18: 8 | D18: Tuesday | E18: 25 | F18: FALSE | G18: Heavy | H18: FALSE
A19: S002 | B19: 46266 | C19: 9 | D19: Tuesday | E19: 28 | F19: FALSE | G19: Light | H19: FALSE
A20: S002 | B20: 46266 | C20: 10 | D20: Tuesday | E20: 24 | F20: FALSE | H20: FALSE
A21: S002 | B21: 46266 | C21: 11 | D21: Tuesday | E21: 36 | F21: FALSE | H21: FALSE
A22: S002 | B22: 46266 | C22: 12 | D22: Tuesday | E22: 26 | F22: FALSE | H22: FALSE
A23: S002 | B23: 46266 | C23: 13 | D23: Tuesday | E23: 39 | F23: FALSE | H23: FALSE
A24: S002 | B24: 46266 | C24: 14 | D24: Tuesday | E24: 22 | F24: FALSE | H24: FALSE
A25: S002 | B25: 46266 | C25: 15 | D25: Tuesday | E25: 27 | F25: FALSE | H25: FALSE
A26: S002 | B26: 46266 | C26: 16 | D26: Tuesday | E26: 35 | F26: FALSE | H26: FALSE
A27: S002 | B27: 46266 | C27: 17 | D27: Tuesday | E27: 29 | F27: FALSE | H27: FALSE
A28: S002 | B28: 46266 | C28: 18 | D28: Tuesday | E28: 33 | F28: FALSE | G28: Light | H28: TRUE
A29: S002 | B29: 46266 | C29: 19 | D29: Tuesday | E29: 41 | F29: TRUE | H29: FALSE
A30: S002 | B30: 46266 | C30: 20 | D30: Tuesday | E30: 55 | F30: TRUE | H30: FALSE
A31: S002 | B31: 46266 | C31: 21 | D31: Tuesday | E31: 39 | F31: TRUE | G31: Heavy | H31: FALSE
A32: S002 | B32: 46266 | C32: 22 | D32: Tuesday | E32: 32 | F32: FALSE | H32: FALSE
A33: S002 | B33: 46266 | C33: 23 | D33: Tuesday | E33: 42 | F33: FALSE | H33: FALSE
A34: S003 | B34: 46266 | C34: 8 | D34: Tuesday | E34: 30 | F34: FALSE | H34: FALSE
A35: S003 | B35: 46266 | C35: 9 | D35: Tuesday | E35: 30 | F35: FALSE | H35: FALSE
A36: S003 | B36: 46266 | C36: 10 | D36: Tuesday | E36: 27 | F36: FALSE | H36: FALSE
A37: S003 | B37: 46266 | C37: 11 | D37: Tuesday | E37: 38 | F37: FALSE | H37: FALSE
A38: S003 | B38: 46266 | C38: 12 | D38: Tuesday | E38: 46 | F38: FALSE | H38: FALSE
A39: S003 | B39: 46266 | C39: 13 | D39: Tuesday | E39: 40 | F39: FALSE | H39: FALSE
A40: S003 | B40: 46266 | C40: 14 | D40: Tuesday | E40: 34 | F40: FALSE | G40: Light | H40: FALSE
...

Sheet Customers
A1: customer_id | B1: city | C1: signup_date | D1: orders_in_dataset | E1: avg_delivery_rating_1_to_5 | F1: repeat_customer_flag | G1: support_tickets_count | H1: primary_ticket_reason | I1: refunds_and_goodwill_credits_inr | J1: repeat_order_in_dataset_flag
A2: C0001 | B2: Mumbai | C2: 45691 | D2: 7 | E2: 4.4 | F2: TRUE | G2: 0 | I2: 0 | J2: TRUE
A3: C0002 | B3: Hyderabad | C3: 45429 | D3: 4 | E3: 4.5 | F3: TRUE | G3: 1 | H3: Payment issue | I3: 25 | J3: TRUE
A4: C0003 | B4: Hyderabad | C4: 45824 | D4: 5 | E4: 5 | F4: TRUE | G4: 0 | I4: 0 | J4: TRUE
A5: C0004 | B5: Pune | C5: 45747 | D5: 8 | E5: 4.6 | F5: TRUE | G5: 0 | I5: 0 | J5: TRUE
A6: C0005 | B6: Pune | C6: 45531 | D6: 8 | E6: 4.9 | F6: TRUE | G6: 5 | H6: Damaged item | I6: 0 | J6: TRUE
A7: C0006 | B7: Delhi | C7: 45876 | D7: 8 | E7: 5 | F7: TRUE | G7: 1 | H7: Damaged item | I7: 50 | J7: TRUE
A8: C0007 | B8: Bengaluru | C8: 46062 | D8: 7 | E8: 4.4 | F8: TRUE | G8: 2 | H8: Late delivery | I8: 150 | J8: TRUE
A9: C0008 | B9: Bengaluru | C9: 45920 | D9: 5 | E9: 5 | F9: TRUE | G9: 1 | H9: Late delivery | I9: 75 | J9: TRUE
A10: C0009 | B10: Bengaluru | C10: 45464 | D10: 5 | E10: 5 | F10: TRUE | G10: 1 | H10: Other | I10: 0 | J10: TRUE
A11: C0010 | B11: Hyderabad | C11: 46135 | D11: 6 | E11: 4.6 | F11: TRUE | G11: 2 | H11: Missing item | I11: 100 | J11: TRUE
A12: C0011 | B12: Hyderabad | C12: 45865 | D12: 5 | E12: 5 | F12: TRUE | G12: 3 | H12: Damaged item | I12: 225 | J12: TRUE
A13: C0012 | B13: Bengaluru | C13: 45947 | D13: 6 | E13: 5 | F13: TRUE | G13: 1 | H13: Payment issue | I13: 50 | J13: TRUE
A14: C0013 | B14: Bengaluru | C14: 45979 | D14: 3 | E14: 5 | F14: TRUE | G14: 0 | I14: 0 | J14: TRUE
A15: C0014 | B15: Mumbai | C15: 45400 | D15: 9 | E15: 5 | F15: TRUE | G15: 1 | H15: Other | I15: 50 | J15: TRUE
A16: C0015 | B16: Delhi | C16: 46211 | D16: 5 | E16: 4.9 | F16: TRUE | G16: 3 | H16: Payment issue | I16: 225 | J16: TRUE
A17: C0016 | B17: Hyderabad | C17: 45404 | D17: 4 | E17: 5 | F17: TRUE | G17: 2 | H17: Missing item | I17: 0 | J17: TRUE
A18: C0017 | B18: Hyderabad | C18: 45934 | D18: 6 | E18: 4.6 | F18: TRUE | G18: 2 | H18: Other | I18: 150 | J18: TRUE
A19: C0018 | B19: Pune | C19: 45609 | D19: 5 | E19: 4.1 | F19: TRUE | G19: 0 | I19: 0 | J19: TRUE
A20: C0019 | B20: Bengaluru | C20: 45998 | D20: 4 | E20: 4.6 | F20: TRUE | G20: 4 | H20: Damaged item | I20: 0 | J20: TRUE
A21: C0020 | B21: Mumbai | C21: 45474 | D21: 4 | E21: 4 | F21: TRUE | G21: 2 | H21: Missing item | I21: 150 | J21: TRUE
A22: C0021 | B22: Hyderabad | C22: 45792 | D22: 7 | E22: 4.3 | F22: TRUE | G22: 2 | H22: Other | I22: 50 | J22: TRUE
A23: C0022 | B23: Pune | C23: 45483 | D23: 6 | E23: 4.9 | F23: TRUE | G23: 2 | H23: Payment issue | I23: 100 | J23: TRUE
A24: C0023 | B24: Pune | C24: 45648 | D24: 3 | E24: 5 | F24: TRUE | G24: 1 | H24: Damaged item | I24: 0 | J24: TRUE
A25: C0024 | B25: Pune | C25: 45809 | D25: 8 | E25: 5 | F25: TRUE | G25: 2 | H25: Payment issue | I25: 0 | J25: TRUE
A26: C0025 | B26: Pune | C26: 45829 | D26: 13 | E26: 4.5 | F26: TRUE | G26: 5 | H26: Other | I26: 0 | J26: TRUE
A27: C0026 | B27: Delhi | C27: 45721 | D27: 6 | E27: 4.6 | F27: TRUE | G27: 3 | H27: Payment issue | I27: 225 | J27: TRUE
A28: C0027 | B28: Bengaluru | C28: 45939 | D28: 7 | E28: 4.1 | F28: TRUE | G28: 2 | H28: Other | I28: 50 | J28: TRUE
A29: C0028 | B29: Pune | C29: 45483 | D29: 7 | E29: 4.2 | F29: TRUE | G29: 6 | H29: Damaged item | I29: 150 | J29: TRUE
A30: C0029 | B30: Pune | C30: 46185 | D30: 4 | E30: 5 | F30: TRUE | G30: 3 | H30: Payment issue | I30: 225 | J30: TRUE
A31: C0030 | B31: Hyderabad | C31: 45537 | D31: 5 | E31: 4.6 | F31: TRUE | G31: 0 | I31: 0 | J31: TRUE
A32: C0031 | B32: Pune | C32: 45848 | D32: 6 | E32: 5 | F32: TRUE | G32: 1 | H32: Late delivery | I32: 50 | J32: TRUE
A33: C0032 | B33: Mumbai | C33: 45551 | D33: 7 | E33: 5 | F33: TRUE | G33: 3 | H33: Damaged item | I33: 225 | J33: TRUE
A34: C0033 | B34: Bengaluru | C34: 45933 | D34: 7 | E34: 4 | F34: TRUE | G34: 1 | H34: Other | I34: 0 | J34: TRUE
A35: C0034 | B35: Hyderabad | C35: 45901 | D35: 8 | E35: 4.4 | F35: TRUE | G35: 1 | H35: Damaged item | I35: 0 | J35: TRUE
A36: C0035 | B36: Delhi | C36: 46055 | D36: 9 | E36: 4.7 | F36: TRUE | G36: 2 | H36: Missing item | I36: 100 | J36: TRUE
A37: C0036 | B37: Hyderabad | C37: 45429 | D37: 1 | E37: 5 | F37: FALSE | G37: 0 | I37: 0 | J37: FALSE
A38: C0037 | B38: Mumbai | C38: 45887 | D38: 2 | E38: 3.8 | F38: TRUE | G38: 2 | H38: Other | I38: 0 | J38: TRUE
A39: C0038 | B39: Mumbai | C39: 45878 | D39: 3 | E39: 4.5 | F39: TRUE | G39: 1 | H39: Damaged item | I39: 25 | J39: TRUE
A40: C0039 | B40: Bengaluru | C40: 46128 | D40: 6 | E40: 5 | F40: TRUE | G40: 3 | H40: Late delivery | I40: 0 | J40: TRUE
...

Sheet Guide
A1: Guide: where to find each calculation
A2: Blinkit Milestone 3 · Prepared by Hriday Pratim Barman · independent case-study analysis, not an official Blinkit report
A4: Sheet | B4: What it contains | C4: Start here for
A5: Orders, Stores, Riders, Demand, Customers | B5: The five original sheets, unchanged. Every new sheet links to them with formulas. | C5: Raw data
A6: Rules | B6: The agreed rules and the assumptions still to confirm. | C6: How on time, peak, cancellations and blanks are treated
A7: Metrics | B7: North Star and its range, cancellation classes, issue-tree counts and % of E, average and P90 times, promise, stage estimates, coverage of Demand. | C7: Numbers on Slides 1 and 2
A8: Hypotheses | B8: H1–H6 with the status used in the submission and live evidence text. | C8: Slide 3 summary
A9: Tests_Proportions | B9: Two-group percentage comparisons with inputs, SE and 95% CI in percentage points. | C9: H1, H2 rain, H3, H4, H6, distance, event days
A10: Tests_Means | B10: Two-group average comparisons (estimated wait and picking, promise, actual time). | C10: H1 and H2 minutes
A11: Tests_Correlations | B11: Correlations with Fisher-z 95% CI: stores, customers, traffic, promise vs distance, picking vs wait. | C11: H4, H5, traffic
A12: Breakdowns | B12: Rates by distance band, cut-off, rain, load quartile and city; customer averages; quartile cut-offs. | C12: Robustness checks and chart values
A13: Checks | B13: Totals, original-sheet integrity, duplicate IDs, unmatched keys, missing values, join duplication, formula errors, and agreement with the submission. | C13: Confirming every number
A14: Calc_Orders | B14: One formula row per order: flags (delivered, late, severe, peak, eligible), cancellation class, rain, Demand match, load, store and rider lookups. | C14: Tracing any single order
A15: Calc_Demand | B15: One row per Demand store-hour with the number of Orders-sheet rows in it. | C15: Coverage of the Demand population
... A18: Reading tips | B18: Green cells are results. Yellow headers have filters. "pts" = percentage points. Blank = missing or not applicable, never zero. Formula columns show the exact formula as text; the result column holds the live formula. | C18: Colour and format legend

Sheet Rules
A1: Rules and assumptions used in every calculation
A2: Rules agreed for the final submission. Items marked "Assumption to confirm" are not stated in the data.
A4: # | B4: Rule | C4: How it is applied | D4: Type
A5: 1 | B5: On time | C5: Delivered at or before the original checkout deadline: delay_min ≤ 0 (actual_delivery_at − promised_delivery_at). | D5: Agreed rule
A6: 2 | B6: Timestamp meanings | C6: actual_delivery_at is taken as confirmed customer handover, and promised_delivery_at as the original checkout promise (not an updated ETA). | D6: Assumption to confirm
A7: 3 | B7: Company-caused cancellations | C7: cancellation_reason = Rider unavailable or Item unavailable. Counted in the North Star (L1-C). | D7: Agreed rule
A8: 4 | B8: Unresolved cancellations | C8: Payment issue and Customer cancelled stay outside E. "Customer cancelled" is a recorded category; it does not establish the cause. | D8: Agreed rule
A9: 5 | B9: North Star | C9: On-time ÷ eligible orders (delivered + company-caused cancellations). Provisional; range shown with all orders as the denominator. | D9: Agreed rule
A10: 6 | B10: Severely late | C10: More than 5 minutes late. Our analytical cut-off; rechecked at 3 and 7 minutes (Breakdowns). | D10: Analytical choice
A11: 7 | B11: Peak | C11: Order placed from 19:00 up to, but not including, 22:00 (order_hour 19, 20, 21). Checked against is_peak_hour. | D11: Agreed rule
A12: 8 | B12: Blank rain | C12: A blank rain_condition means no rain ("None"). | D12: Agreed rule (confirmed)
A13: 9 | B13: Stage durations | C13: picking, rider-wait and travel minutes are estimates supplied in the data, not recorded timestamps. | D13: Data limitation
A14: 10 | B14: Customer level | C14: Tickets, refunds and ratings are analysed per customer in Customer_Summary; they are never copied onto order rows. | D14: Agreed rule
A15: 11 | B15: Demand matching | C15: An order matches Demand on store_id + date + hour. Demand (128,528 orders) is the population; the 1,500 Orders rows are part of it. Whether these results apply more widely depends on how the sample was selected. That information is missing. | D15: Agreed rule
A16: 12 | B16: Missing values | C16: Blank stays blank in calculations (shown as an empty cell), never zero. | D16: Agreed rule
... A18: 14 | B18: Confidence intervals | C18: Normal-approximation 95% intervals for differences and Fisher-z intervals for correlations. Less reliable for small groups. | D18: Method

Sheet Metrics
A1: Metrics: North Star, cancellations, issue tree, times and stages
A2: Every result is a live formula. [M12] in the Formula column means the Result of row M12. % results are stored as fractions; the denominator is named beside each one.
A3: ID | B3: Section | C3: Measure | D3: Purpose | E3: Source sheet: columns | F3: Formula | G3: Result | H3: Unit / denominator | I3: Explanation
A4: M01 | B4: Totals | C4: Orders placed | D4: Population of this analysis | E4: Orders: order_id | F4: =ROWS(o_order_id) | G4: =ROWS(o_order_id) -> 1500 | H4: Orders (count) | I4: All 1,500 order rows, delivered and cancelled.
A5: M02 | B5: Totals | C5: Delivered orders | D5: Base for delivery rates | E5: Orders: order_status | F5: =COUNTIFS(o_status,"Delivered") | G5: =COUNTIFS(o_status,"Delivered") -> 1455 | H5: Orders (count) | I5: order_status = Delivered.
A6: M03 | B6: Totals | C6: Cancelled orders | D6: Base for cancellation rules | E6: Orders: order_status | F6: =COUNTIFS(o_status,"Cancelled") | G6: =COUNTIFS(o_status,"Cancelled") -> 45 | H6: Orders (count) | I6: order_status = Cancelled.
A7: M04 | B7: Cancellations | C7: Rider unavailable (C1) | D7: Company-caused cancellation | E7: Orders: cancellation_reason | F7: =COUNTIFS(o_reason,"Rider unavailable") | G7: =COUNTIFS(o_reason,"Rider unavailable") -> 18 | H7: Orders (count) | I7: Agreed rule: company-caused.
A8: M05 | B8: Cancellations | C8: Item unavailable (C2) | D8: Company-caused cancellation | E8: Orders: cancellation_reason | F8: =COUNTIFS(o_reason,"Item unavailable") | G8: =COUNTIFS(o_reason,"Item unavailable") -> 8 | H8: Orders (count) | I8: Agreed rule: company-caused.
A9: M06 | B9: Cancellations | C9: Company-caused cancellations (L1-C) | D9: Counted in the North Star | E9: Metrics: M04, M05 | F9: =[M04]+[M05] (cells: =$G$7+$G$8) | G9: =$G$7+$G$8 -> 26 | H9: Orders (count) | I9: C1 + C2.
A10: M07 | B10: Cancellations | C10: Payment issue | D10: Unresolved cancellation | E10: Orders: cancellation_reason | F10: =COUNTIFS(o_reason,"Payment issue") | G10: =COUNTIFS(o_reason,"Payment issue") -> 8 | H10: Orders (count) | I10: Cause not confirmed; outside the North Star for now.
A11: M08 | B11: Cancellations | C11: Customer cancelled | D11: Unresolved cancellation | E11: Orders: cancellation_reason | F11: =COUNTIFS(o_reason,"Customer cancelled") | G11: =COUNTIFS(o_reason,"Customer cancelled") -> 11 | H11: Orders (count) | I11: Recorded category only: it does not establish the cause, or for certain who pressed Cancel.
A12: M09 | B12: Cancellations | C12: Unresolved cancellations | D12: Kept outside E | E12: Metrics: M07, M08 | F12: =[M07]+[M08] (cells: =$G$10+$G$11) | G12: =$G$10+$G$11 -> 19 | H12: Orders (count) | I12: Payment issue + Customer cancelled.
A13: M10 | B13: Cancellations | C13: All cancellation reasons accounted for | D13: Check | E13: Metrics: M03, M06, M09 | F13: =[M03]-[M06]-[M09] (cells: =$G$6-$G$9-$G$12) | G13: =$G$6-$G$9-$G$12 -> 0 | H13: Orders (count); should be 0 | I13: Cancelled orders not in either class.
A14: M11 | B14: North Star | C14: Eligible orders (E) | D14: North Star denominator | E14: Metrics: M02, M06 | F14: =[M02]+[M06] (cells: =$G$5+$G$9) | G14: =$G$5+$G$9 -> 1481 | H14: Orders (count) | I14: Delivered + company-caused cancellations.
A15: M12 | B15: Issue tree | C15: L1-A On time | D15: Numerator of the North Star | E15: Calc_Orders: Late | F15: =COUNTIFS(c_late,0) | G15: =COUNTIFS(c_late,0) -> 1092 | H15: Orders (count) | I15: Delivered at or before the original checkout deadline (delay_min ≤ 0). Timestamp meanings are assumptions to confirm.
A16: M13 | B16: Issue tree | C16: L1-B Late | D16: Delivered after the deadline | E16: Calc_Orders: Late | F16: =COUNTIFS(c_late,1) | G16: =COUNTIFS(c_late,1) -> 363 | H16: Orders (count) | I16: delay_min > 0.
A17: M14 | B17: Issue tree | C17: B1 Slightly late (0–5 min) | D17: Size of small misses | E17: Calc_Orders: Late, Severe | F17: =COUNTIFS(c_late,1,c_sev,0) | G17: =COUNTIFS(c_late,1,c_sev,0) -> 155 | H17: Orders (count) | I17: More than 0 and up to 5 minutes late.
A18: M15 | B18: Issue tree | C18: B2 Severely late (>5 min) | D18: Size of large misses | E18: Calc_Orders: Severe | F18: =COUNTIFS(c_sev,1) | G18: =COUNTIFS(c_sev,1) -> 208 | H18: Orders (count) | I18: More than 5 minutes late. 5 minutes is our analytical choice.
A19: M16 | B19: Issue tree | C19: B1a Slightly late, peak | D19: When small misses happen | E19: Calc_Orders: Late, Severe, Peak | F19: =COUNTIFS(c_late,1,c_sev,0,c_peak,1) | G19: =COUNTIFS(c_late,1,c_sev,0,c_peak,1) -> 11 | H19: Orders (count) | I19: Peak = placed 19:00 up to 22:00.
A20: M17 | B20: Issue tree | C20: B1b Slightly late, off-peak | D20: When small misses happen | E20: Calc_Orders: Late, Severe, Peak | F20: =COUNTIFS(c_late,1,c_sev,0,c_peak,0) | G20: =COUNTIFS(c_late,1,c_sev,0,c_peak,0) -> 144 | H20: Orders (count)
A21: M18 | B21: Issue tree | C21: B2a Severely late, peak | D21: When large misses happen | E21: Calc_Orders: Severe, Peak | F21: =COUNTIFS(c_sev,1,c_peak,1) | G21: =COUNTIFS(c_sev,1,c_peak,1) -> 69 | H21: Orders (count)
A22: M19 | B22: Issue tree | C22: B2b Severely late, off-peak | D22: When large misses happen | E22: Calc_Orders: Severe, Peak | F22: =COUNTIFS(c_sev,1,c_peak,0) | G22: =COUNTIFS(c_sev,1,c_peak,0) -> 139 | H22: Orders (count)
A23: M20 | B23: North Star | C23: North Star (provisional) | D23: Headline metric | E23: Metrics: M12, M11 | F23: =[M12]/[M11] (cells: =$G$15/$G$14) | G23: =$G$15/$G$14 -> 0.73733964 | H23: % of E (eligible orders) | I23: On-time fulfilment = on time ÷ eligible orders. Provisional because 19 cancellations are unresolved.
A24: M21 | B24: North Star | C24: North Star, lower end of range | D24: Effect of unresolved cancellations | E24: Metrics: M12, M01 | F24: =[M12]/[M01] (cells: =$G$15/$G$4) | G24: =$G$15/$G$4 -> 0.728 | H24: % of all orders placed | I24: As if every unresolved cancellation were company-caused.
A25: M22 | B25: North Star | C25: On time among delivered | D25: Delivery performance only | E25: Metrics: M12, M02 | F25: =[M12]/[M02] (cells: =$G$15/$G$5) | G25: =$G$15/$G$5 -> 0.75051546 | H25: % of delivered orders | I25: Ignores cancellations.
A26: M23 | B26: North Star | C26: Cancellation rate | D26: Guardrail | E26: Metrics: M03, M01 | F26: =[M03]/[M01] (cells: =$G$6/$G$4) | G26: =$G$6/$G$4 -> 0.03 | H26: % of all orders placed
A27: P12 | B27: Issue tree % | C27: L1-A On time, % of E | D27: Issue-tree share | E27: Metrics: M12, M11 | F27: =[M12]/[M11] (cells: =$G$15/$G$14) | G27: =$G$15/$G$14 -> 0.73733964 | H27: % of E (1,481 eligible orders) | I27: Group count ÷ E × 100. Child shares may differ from the parent by 0.1 because of rounding.
A28: P13 | B28: Issue tree % | C28: L1-B Late, % of E | D28: Issue-tree share | E28: Metrics: M13, M11 | F28: =[M13]/[M11] (cells: =$G$16/$G$14) | G28: =$G$16/$G$14 -> 0.24510466 | H28: % of E (1,481 eligible orders) | I28: Group count ÷ E × 100. Child shares may differ from the parent by 0.1 because of rounding.
A29: P14 | B29: Issue tree % | C29: B1, % of E | D29: Issue-tree share | E29: Metrics: M14, M11 | F29: =[M14]/[M11] (cells: =$G$17/$G$14) | G29: =$G$17/$G$14 -> 0.10465901 | H29: % of E (1,481 eligible orders) | I29: Group count ÷ E × 100. Child shares may differ from the parent by 0.1 because of rounding.
A30: P15 | B30: Issue tree % | C30: B2, % of E | D30: Issue-tree share | E30: Metrics: M15, M11 | F30: =[M15]/[M11] (cells: =$G$18/$G$14) | G30: =$G$18/$G$14 -> 0.14044564 | H30: % of E (1,481 eligible orders) | I30: Group count ÷ E × 100. Child shares may differ from the parent by 0.1 because of rounding.
A31: P16 | B31: Issue tree % | C31: B1a, % of E | D31: Issue-tree share | E31: Metrics: M16, M11 | F31: =[M16]/[M11] (cells: =$G$19/$G$14) | G31: =$G$19/$G$14 -> 0.0074274139 | H31: % of E (1,481 eligible orders) | I31: Group count ÷ E × 100. Child shares may differ from the parent by 0.1 because of rounding.
A32: P17 | B32: Issue tree % | C32: B1b, % of E | D32: Issue-tree share | E32: Metrics: M17, M11 | F32: =[M17]/[M11] (cells: =$G$20/$G$14) | G32: =$G$20/$G$14 -> 0.0972316 | H32: % of E (1,481 eligible orders) | I32: Group count ÷ E × 100. Child shares may differ from the parent by 0.1 because of rounding.
A33: P18 | B33: Issue tree % | C33: B2a, % of E | D33: Issue-tree share | E33: Metrics: M18, M11 | F33: =[M18]/[M11] (cells: =$G$21/$G$14) | G33: =$G$21/$G$14 -> 0.046590142 | H33: % of E (1,481 eligible orders) | I33: Group count ÷ E × 100. Child shares may differ from the parent by 0.1 because of rounding.
A34: P19 | B34: Issue tree % | C34: B2b, % of E | D34: Issue-tree share | E34: Metrics: M19, M11 | F34: =[M19]/[M11] (cells: =$G$22/$G$14) | G34: =$G$22/$G$14 -> 0.093855503 | H34: % of E (1,481 eligible orders) | I34: Group count ÷ E × 100. Child shares may differ from the parent by 0.1 because of rounding.
A35: P06 | B35: Issue tree % | C35: L1-C Company-caused, % of E | D35: Issue-tree share | E35: Metrics: M06, M11 | F35: =[M06]/[M11] (cells: =$G$9/$G$14) | G35: =$G$9/$G$14 -> 0.017555706 | H35: % of E (1,481 eligible orders) | I35: Group count ÷ E × 100. Child shares may differ from the parent by 0.1 because of rounding.
A36: P04 | B36: Issue tree % | C36: C1, % of E | D36: Issue-tree share | E36: Metrics: M04, M11 | F36: =[M04]/[M11] (cells: =$G$7/$G$14) | G36: =$G$7/$G$14 -> 0.01215395 | H36: % of E (1,481 eligible orders) | I36: Group count ÷ E × 100. Child shares may differ from the parent by 0.1 because of rounding.
A37: P05 | B37: Issue tree % | C37: C2, % of E | D37: Issue-tree share | E37: Metrics: M05, M11 | F37: =[M05]/[M11] (cells: =$G$8/$G$14) | G37: =$G$8/$G$14 -> 0.0054017556 | H37: % of E (1,481 eligible orders) | I37: Group count ÷ E × 100. Child shares may differ from the parent by 0.1 because of rounding.
A38: M24 | B38: Issue tree | C38: Tree counts add up (A + B + C − E) | D38: Check | E38: Metrics | F38: =[M12]+[M13]+[M06]-[M11] (cells: =$G$15+$G$16+$G$9-$G$14) | G38: =$G$15+$G$16+$G$9-$G$14 -> 0 | H38: Orders; should be 0 | I38: Each eligible order sits in exactly one final box.
A39: M25 | B39: Times | C39: Average delivery time | D39: Typical speed | E39: Orders: actual_delivery_duration_min, order_status | F39: =AVERAGEIFS(o_actual_min,o_status,"Delivered") | G39: =AVERAGEIFS(o_actual_min,o_status,"Delivered") -> 11.313677 | H39: Minutes; delivered orders | I39: Placement to handover (assumed meaning of actual_delivery_at).
A40: M26 | B40: Times | C40: P90 delivery time | D40: Slow tail | E40: Calc_Orders: Actual min | F40: =PERCENTILE(c_act,0.9) | G40: =PERCENTILE(c_act,0.9) -> 17.2 | H40: Minutes; delivered orders | I40: 9 in 10 delivered orders arrive within this. PERCENTILE = PERCENTILE.INC (linear).
...

Sheet Hypotheses
A1: Hypotheses: ranking and status used in the final submission
A2: Each status points to the evidence rows. Patterns are not proof of cause.
A4: Rank | B4: Hypothesis | C4: Status (as submitted) | D4: Key evidence (live values) | E4: Evidence rows | F4: Limitations
A5: 1 · H1 | B5: Severe delays are more common at 7–10 PM. A store-to-rider bottleneck is one possible explanation. | C5: Supported: severe delays are more common at peak | D5: ="Severely late "&TEXT(Tests_Proportions!$F$5,"0.0%")&" peak vs "&TEXT(Tests_Proportions!$J$5,"0.0%")&" off-peak ("&"95% CI "&TEXT(Tests_Proportions!$M$5,"+0.0;-0.0")&" to "&TEXT(Tests_Proportions!$N$5,"+0.0;-0.0")&" pts"&"). Late at all "&TEXT(Tests_Proportions!$F$6,"0.0%")&" vs "&TEXT(Tests_Proportions!$J$6,"0.0%")&" ("&"95% CI "&TEXT(Tests_Proportions!$M$6,"+0.0;-0.0")&" to "&TEXT(Tests_Proportions!$N$6,"+0.0;-0.0")&" pts"&"). Est. wait "&TEXT(Tests_Means!$K$5,"+0.00;-0.00")&" min." -> Severely late 25.0% peak vs 11.8% off-peak (95% CI +7.8 to +18.6 pts). Late at all 29.0% vs 24.0% (95% CI -0.9 to +10.9 pts). Est. wait +1.02 min. | E5: Tests_Proportions T01, T02; Tests_Means U01, U02; Breakdowns H1 rows | F5: Bottleneck is a possible explanation, not an established cause. No hourly rider availability; wait is an estimate.
A6: 2 · H2 | B6: Promises do not match conditions: shorter at peak and no longer in heavy rain. | C6: Supported at peak; borderline in rain | D6: ="Promise "&TEXT(Tests_Means!$D$7,"0.0")&" vs "&TEXT(Tests_Means!$H$7,"0.0")&" min; actual "&TEXT(Tests_Means!$D$8,"0.00")&" vs "&TEXT(Tests_Means!$H$8,"0.00")&" min. Heavy rain late "&TEXT(Tests_Proportions!$F$7,"0.0%")&" vs "&TEXT(Tests_Proportions!$J$7,"0.0%")&" ("&"95% CI "&TEXT(Tests_Proportions!$M$7,"+0.0;-0.0")&" to "&TEXT(Tests_Proportions!$N$7,"+0.0;-0.0")&" pts"&")." -> Promise 9.6 vs 10.5 min; actual 11.78 vs 11.20 min. Heavy rain late 33.9% vs 24.8% (95% CI +0.0 to +18.3 pts). | E6: Tests_Means U03, U04; Tests_Proportions T03; Breakdowns H2 rows | F6: How the promise is calculated is not in the data.
A7: 3 · H3 | B7: Store-hours busier than the store's usual load run late more often. | C7: Inconclusive; overlaps with peak | D7: ="All hours Q4 vs Q1 "&TEXT(Tests_Proportions!$F$8,"0.0%")&" vs "&TEXT(Tests_Proportions!$J$8,"0.0%")&" ("&"95% CI "&TEXT(Tests_Proportions!$M$8,"+0.0;-0.0")&" to "&TEXT(Tests_Proportions!$N$8,"+0.0;-0.0")&" pts"&"). Off-peak only "&TEXT(Tests_Proportions!$F$9,"0.0%")&" vs "&TEXT(Tests_Proportions!$J$9,"0.0%")&" ("&"95% CI "&TEXT(Tests_Proportions!$M$9,"+0.0;-0.0")&" to "&TEXT(Tests_Proportions!$N$9,"+0.0;-0.0")&" pts"&")." -> All hours Q4 vs Q1 29.1% vs 21.4% (95% CI +1.4 to +14.0 pts). Off-peak only 27.1% vs 21.7% (95% CI -1.5 to +12.3 pts). | E7: Tests_Proportions T04, T05; Breakdowns H3 rows | F7: Every peak hour is high-load, so load and peak cannot be separated.
A8: 4 · H4 | B8: Stores with slower picking deliver late more often. | C8: No clear evidence in this analysis | D8: ="r = "&TEXT(Tests_Correlations!$G$5,"0.00")&" (95% CI "&TEXT(Tests_Correlations!$J$5,"+0.00;-0.00")&" to "&TEXT(Tests_Correlations!$K$5,"+0.00;-0.00")&", n = 20). Slower vs faster half "&TEXT(Tests_Proportions!$F$10,"0.0%")&" vs "&TEXT(Tests_Proportions!$J$10,"0.0%")&" ("&"95% CI "&TEXT(Tests_Proportions!$M$10,"+0.0;-0.0")&" to "&TEXT(Tests_Proportions!$N$10,"+0.0;-0.0")&" pts"&")." -> r = 0.43 (95% CI -0.02 to +0.73, n = 20). Slower vs faster half 26.1% vs 23.9% (95% CI -2.3 to +6.6 pts). | E8: Tests_Correlations R01–R03; Tests_Proportions T06 | F8: Only 20 stores; this does not show picking speed has no effect.
A9: 5 · H5 | B9: Late deliveries drive support tickets and refunds. | C9: No clear evidence in this analysis | D9: ="Tickets r = "&TEXT(Tests_Correlations!$G$9,"0.00")&", refunds r = "&TEXT(Tests_Correlations!$G$10,"0.00")&": no clear straight-line association." -> Tickets r = 0.02, refunds r = 0.08: no clear straight-line association. | E9: Tests_Correlations R05–R07; Breakdowns H5 rows | F9: Tickets are per customer, not per order; the test is weak.
A10: 6 · H6 | B10: New stores are less reliable. | C10: Inconclusive: only two new stores | D10: ="New vs older stores late "&TEXT(Tests_Proportions!$F$11,"0.0%")&" vs "&TEXT(Tests_Proportions!$J$11,"0.0%")&" ("&"95% CI "&TEXT(Tests_Proportions!$M$11,"+0.0;-0.0")&" to "&TEXT(Tests_Proportions!$N$11,"+0.0;-0.0")&" pts"&")." -> New vs older stores late 25.5% vs 24.9% (95% CI -6.8 to +8.0 pts). | E10: Tests_Proportions T07; Tests_Correlations R04 | F10: No clear difference does not prove equal performance.

Sheet Tests_Proportions
A1: Tests_Proportions: differences between two percentages, with 95% confidence intervals
A2: Method: two-proportion normal approximation. SE = √(p1(1−p1)/n1 + p2(1−p2)/n2); 95% CI = (p1 − p2) ± 1.96 × SE. Differences are in percentage points (pts).
A4: ID | B4: Used for | C4: Group A | D4: A count (x1) | E4: A total (n1) | F4: A rate (p1) | G4: Group B | H4: B count (x2) | I4: B total (n2) | J4: B rate (p2) | K4: Difference p1 − p2 (pts) | L4: SE (pts) | M4: 95% CI low (pts) | N4: 95% CI high (pts) | O4: Reading | P4: Inputs (count / total)
A5: T01 | B5: H1 main result | C5: Peak delivered: severely late | D5: =COUNTIFS(c_sev,1,c_peak,1) -> 69 | E5: =COUNTIFS(c_deliv,1,c_peak,1) -> 276 | F5: =D5/E5 -> 0.25 | G5: Off-peak delivered: severely late | H5: =COUNTIFS(c_sev,1,c_peak,0) -> 139 | I5: =COUNTIFS(c_deliv,1,c_peak,0) -> 1179 | J5: =H5/I5 -> 0.11789652 | K5: =(F5-J5)*100 -> 13.210348 | L5: =SQRT(F5*(1-F5)/E5+J5*(1-J5)/I5)*100 -> 2.7704793 | M5: =K5-1.96*L5 -> 7.7802083 | N5: =K5+1.96*L5 -> 18.640487 | O5: =IF(OR(ABS(M5)<0.05,ABS(N5)<0.05),"Borderline: CI edge at about 0",IF(OR(AND(M5>0,N5>0),AND(M5<0,N5<0)),"Clear: CI excludes 0","Not clear: CI includes 0")) -> Clear: CI excludes 0 | P5: x1: =COUNTIFS(c_sev,1,c_peak,1) n1: =COUNTIFS(c_deliv,1,c_peak,1) x2: =COUNTIFS(c_sev,1,c_peak,0) n2: =COUNTIFS(c_deliv,1,c_peak,0)
A6: T02 | B6: H1: late at all | C6: Peak delivered: late | D6: =COUNTIFS(c_late,1,c_peak,1) -> 80 | E6: =COUNTIFS(c_deliv,1,c_peak,1) -> 276 | F6: =D6/E6 -> 0.28985507 | G6: Off-peak delivered: late | H6: =COUNTIFS(c_late,1,c_peak,0) -> 283 | I6: =COUNTIFS(c_deliv,1,c_peak,0) -> 1179 | J6: =H6/I6 -> 0.24003393 | K6: =(F6-J6)*100 -> 4.9821145 | L6: =SQRT(F6*(1-F6)/E6+J6*(1-J6)/I6)*100 -> 3.0008602 | M6: =K6-1.96*L6 -> -0.89957152 | N6: =K6+1.96*L6 -> 10.863801 | O6: =IF(OR(ABS(M6)<0.05,ABS(N6)<0.05),"Borderline: CI edge at about 0",IF(OR(AND(M6>0,N6>0),AND(M6<0,N6<0)),"Clear: CI excludes 0","Not clear: CI includes 0")) -> Not clear: CI includes 0 | P6: x1: =COUNTIFS(c_late,1,c_peak,1) n1: =COUNTIFS(c_deliv,1,c_peak,1) x2: =COUNTIFS(c_late,1,c_peak,0) n2: =COUNTIFS(c_deliv,1,c_peak,0)
A7: T03 | B7: H2: heavy rain | C7: Heavy rain delivered: late | D7: =COUNTIFS(c_rain,"Heavy",c_late,1) -> 38 | E7: =COUNTIFS(c_rain,"Heavy",c_deliv,1) -> 112 | F7: =D7/E7 -> 0.33928571 | G7: No rain delivered: late | H7: =COUNTIFS(c_rain,"None",c_late,1) -> 257 | I7: =COUNTIFS(c_rain,"None",c_deliv,1) -> 1038 | J7: =H7/I7 -> 0.24759152 | K7: =(F7-J7)*100 -> 9.1694192 | L7: =SQRT(F7*(1-F7)/E7+J7*(1-J7)/I7)*100 -> 4.6701137 | M7: =K7-1.96*L7 -> 0.015996452 | N7: =K7+1.96*L7 -> 18.322842 | O7: =IF(OR(ABS(M7)<0.05,ABS(N7)<0.05),"Borderline: CI edge at about 0",IF(OR(AND(M7>0,N7>0),AND(M7<0,N7<0)),"Clear: CI excludes 0","Not clear: CI includes 0")) -> Borderline: CI edge at about 0 | P7: x1: =COUNTIFS(c_rain,"Heavy",c_late,1) n1: =COUNTIFS(c_rain,"Heavy",c_deliv,1) x2: =COUNTIFS(c_rain,"None",c_late,1) n2: =COUNTIFS(c_rain,"None",c_deliv,1)
A8: T04 | B8: H3: all hours | C8: Highest load quartile (Q4): late | D8: =COUNTIFS(c_qall,4,c_late,1) -> 105 | E8: =COUNTIFS(c_qall,4) -> 361 | F8: =D8/E8 -> 0.29085873 | G8: Lowest load quartile (Q1): late | H8: =COUNTIFS(c_qall,1,c_late,1) -> 79 | I8: =COUNTIFS(c_qall,1) -> 369 | J8: =H8/I8 -> 0.21409214 | K8: =(F8-J8)*100 -> 7.6766585 | L8: =SQRT(F8*(1-F8)/E8+J8*(1-J8)/I8)*100 -> 3.2052104 | M8: =K8-1.96*L8 -> 1.3944462 | N8: =K8+1.96*L8 -> 13.958871 | O8: =IF(OR(ABS(M8)<0.05,ABS(N8)<0.05),"Borderline: CI edge at about 0",IF(OR(AND(M8>0,N8>0),AND(M8<0,N8<0)),"Clear: CI excludes 0","Not clear: CI includes 0")) -> Clear: CI excludes 0 | P8: x1: =COUNTIFS(c_qall,4,c_late,1) n1: =COUNTIFS(c_qall,4) x2: =COUNTIFS(c_qall,1,c_late,1) n2: =COUNTIFS(c_qall,1)
A9: T05 | B9: H3: off-peak only | C9: Off-peak Q4: late | D9: =COUNTIFS(c_qop,4,c_late,1) -> 79 | E9: =COUNTIFS(c_qop,4) -> 292 | F9: =D9/E9 -> 0.27054795 | G9: Off-peak Q1: late | H9: =COUNTIFS(c_qop,1,c_late,1) -> 65 | I9: =COUNTIFS(c_qop,1) -> 300 | J9: =H9/I9 -> 0.21666667 | K9: =(F9-J9)*100 -> 5.3881279 | L9: =SQRT(F9*(1-F9)/E9+J9*(1-J9)/I9)*100 -> 3.5236386 | M9: =K9-1.96*L9 -> -1.5182038 | N9: =K9+1.96*L9 -> 12.29446 | O9: =IF(OR(ABS(M9)<0.05,ABS(N9)<0.05),"Borderline: CI edge at about 0",IF(OR(AND(M9>0,N9>0),AND(M9<0,N9<0)),"Clear: CI excludes 0","Not clear: CI includes 0")) -> Not clear: CI includes 0 | P9: x1: =COUNTIFS(c_qop,4,c_late,1) n1: =COUNTIFS(c_qop,4) x2: =COUNTIFS(c_qop,1,c_late,1) n2: =COUNTIFS(c_qop,1)
A10: T06 | B10: H4: picking speed | C10: Slower-picking stores: late | D10: =COUNTIFS(c_slow,1,c_late,1) -> 179 | E10: =COUNTIFS(c_slow,1,c_deliv,1) -> 686 | F10: =D10/E10 -> 0.26093294 | G10: Faster-picking stores: late | H10: =COUNTIFS(c_slow,0,c_late,1) -> 184 | I10: =COUNTIFS(c_slow,0,c_deliv,1) -> 769 | J10: =H10/I10 -> 0.23927178 | K10: =(F10-J10)*100 -> 2.1661163 | L10: =SQRT(F10*(1-F10)/E10+J10*(1-J10)/I10)*100 -> 2.2755572 | M10: =K10-1.96*L10 -> -2.2939757 | N10: =K10+1.96*L10 -> 6.6262083 | O10: =IF(OR(ABS(M10)<0.05,ABS(N10)<0.05),"Borderline: CI edge at about 0",IF(OR(AND(M10>0,N10>0),AND(M10<0,N10<0)),"Clear: CI excludes 0","Not clear: CI includes 0")) -> Not clear: CI includes 0 | P10: x1: =COUNTIFS(c_slow,1,c_late,1) n1: =COUNTIFS(c_slow,1,c_deliv,1) x2: =COUNTIFS(c_slow,0,c_late,1) n2: =COUNTIFS(c_slow,0,c_deliv,1)
A11: T07 | B11: H6: new stores | C11: New stores (<180 days): late | D11: =COUNTIFS(c_new,1,c_late,1) -> 38 | E11: =COUNTIFS(c_new,1,c_deliv,1) -> 149 | F11: =D11/E11 -> 0.25503356 | G11: Older stores: late | H11: =COUNTIFS(c_new,0,c_late,1) -> 325 | I11: =COUNTIFS(c_new,0,c_deliv,1) -> 1306 | J11: =H11/I11 -> 0.24885145 | K11: =(F11-J11)*100 -> 0.61821022 | L11: =SQRT(F11*(1-F11)/E11+J11*(1-J11)/I11)*100 -> 3.7659498 | M11: =K11-1.96*L11 -> -6.7630513 | N11: =K11+1.96*L11 -> 7.9994718 | O11: =IF(OR(ABS(M11)<0.05,ABS(N11)<0.05),"Borderline: CI edge at about 0",IF(OR(AND(M11>0,N11>0),AND(M11<0,N11<0)),"Clear: CI excludes 0","Not clear: CI includes 0")) -> Not clear: CI includes 0 | P11: x1: =COUNTIFS(c_new,1,c_late,1) n1: =COUNTIFS(c_new,1,c_deliv,1) x2: =COUNTIFS(c_new,0,c_late,1) n2: =COUNTIFS(c_new,0,c_deliv,1)
A12: T08 | B12: Other: distance | C12: Up to 1 km: late | D12: =COUNTIFS(c_dist,"<=1",c_late,1) -> 77 | E12: =COUNTIFS(c_dist,"<=1") -> 356 | F12: =D12/E12 -> 0.21629213 | G12: Over 4 km: late | H12: =COUNTIFS(c_dist,">4",c_late,1) -> 21 | I12: =COUNTIFS(c_dist,">4") -> 64 | J12: =H12/I12 -> 0.328125 | K12: =(F12-J12)*100 -> -11.183287 | L12: =SQRT(F12*(1-F12)/E12+J12*(1-J12)/I12)*100 -> 6.2616475 | M12: =K12-1.96*L12 -> -23.456116 | N12: =K12+1.96*L12 -> 1.0895425 | O12: =IF(OR(ABS(M12)<0.05,ABS(N12)<0.05),"Borderline: CI edge at about 0",IF(OR(AND(M12>0,N12>0),AND(M12<0,N12<0)),"Clear: CI excludes 0","Not clear: CI includes 0")) -> Not clear: CI includes 0 | P12: x1: =COUNTIFS(c_dist,"<=1",c_late,1) n1: =COUNTIFS(c_dist,"<=1") x2: =COUNTIFS(c_dist,">4",c_late,1) n2: =COUNTIFS(c_dist,">4")
A13: T09 | B13: Other: event days | C13: Event days: late | D13: =COUNTIFS(c_event,1,c_late,1) -> 9 | E13: =COUNTIFS(c_event,1,c_deliv,1) -> 63 | F13: =D13/E13 -> 0.14285714 | G13: Other days: late | H13: =COUNTIFS(c_event,0,c_late,1) -> 354 | I13: =COUNTIFS(c_event,0,c_deliv,1) -> 1392 | J13: =H13/I13 -> 0.25431034 | K13: =(F13-J13)*100 -> -11.14532 | L13: =SQRT(F13*(1-F13)/E13+J13*(1-J13)/I13)*100 -> 4.5605567 | M13: =K13-1.96*L13 -> -20.084011 | N13: =K13+1.96*L13 -> -2.206629 | O13: =IF(OR(ABS(M13)<0.05,ABS(N13)<0.05),"Borderline: CI edge at about 0",IF(OR(AND(M13>0,N13>0),AND(M13<0,N13<0)),"Clear: CI excludes 0","Not clear: CI includes 0")) -> Clear: CI excludes 0 | P13: x1: =COUNTIFS(c_event,1,c_late,1) n1: =COUNTIFS(c_event,1,c_deliv,1) x2: =COUNTIFS(c_event,0,c_late,1) n2: =COUNTIFS(c_event,0,c_deliv,1)
A15: Note: the normal approximation is less reliable for small groups (for example 64 orders over 4 km, 63 on event days). "Not clear" means the data cannot tell the groups apart; it does not prove they are the same.

Sheet Tests_Means
A1: Tests_Means: differences between two averages, with 95% confidence intervals
A2: Method: Welch-style normal approximation. SE = √(s1²/n1 + s2²/n2) using sample SD (STDEV); 95% CI = (m1 − m2) ± 1.96 × SE. Stage times are estimates.
A4: ID | B4: Used for | C4: Group A | D4: Mean A (min) | E4: SD A | F4: n A | G4: Group B | H4: Mean B (min) | I4: SD B | J4: n B | K4: Difference A − B (min) | L4: SE (min) | M4: 95% CI low (min) | N4: 95% CI high (min) | O4: Reading | P4: Inputs
A5: U01 | B5: H1: estimated rider wait | C5: Peak | D5: =AVERAGE(c_wpk) -> 4.4137681 | E5: =STDEV(c_wpk) -> 2.3156132 | F5: =COUNT(c_wpk) -> 276 | G5: Off-peak | H5: =AVERAGE(c_wop) -> 3.3937235 | I5: =STDEV(c_wop) -> 1.8633936 | J5: =COUNT(c_wop) -> 1179 | K5: =D5-H5 -> 1.0200446 | L5: =SQRT(E5^2/F5+I5^2/J5) -> 0.14957552 | M5: =K5-1.96*L5 -> 0.72687659 | N5: =K5+1.96*L5 -> 1.3132126 | O5: =IF(OR(AND(M5>0,N5>0),AND(M5<0,N5<0)),"Clear: CI excludes 0","Not clear: CI includes 0") -> Clear: CI excludes 0 | P5: Calc_Orders ranges c_wpk and c_wop (delivered orders only)
A6: U02 | B6: H1: estimated picking | C6: Peak | D6: =AVERAGE(c_ppk) -> 3.1619565 | E6: =STDEV(c_ppk) -> 1.5220447 | F6: =COUNT(c_ppk) -> 276 | G6: Off-peak | H6: =AVERAGE(c_pop) -> 3.6914334 | I6: =STDEV(c_pop) -> 1.3857887 | J6: =COUNT(c_pop) -> 1179 | K6: =D6-H6 -> -0.5294769 | L6: =SQRT(E6^2/F6+I6^2/J6) -> 0.10011193 | M6: =K6-1.96*L6 -> -0.72569628 | N6: =K6+1.96*L6 -> -0.33325752 | O6: =IF(OR(AND(M6>0,N6>0),AND(M6<0,N6<0)),"Clear: CI excludes 0","Not clear: CI includes 0") -> Clear: CI excludes 0 | P6: Calc_Orders ranges c_ppk and c_pop (delivered orders only)
A7: U03 | B7: H2: promised minutes | C7: Peak | D7: =AVERAGE(c_prpk) -> 9.6018116 | E7: =STDEV(c_prpk) -> 1.1628008 | F7: =COUNT(c_prpk) -> 276 | G7: Off-peak | H7: =AVERAGE(c_prop) -> 10.503562 | I7: =STDEV(c_prop) -> 1.2568201 | J7: =COUNT(c_prop) -> 1179 | K7: =D7-H7 -> -0.90175075 | L7: =SQRT(E7^2/F7+I7^2/J7) -> 0.07898551 | M7: =K7-1.96*L7 -> -1.0565623 | N7: =K7+1.96*L7 -> -0.74693915 | O7: =IF(OR(AND(M7>0,N7>0),AND(M7<0,N7<0)),"Clear: CI excludes 0","Not clear: CI includes 0") -> Clear: CI excludes 0 | P7: Calc_Orders ranges c_prpk and c_prop (delivered orders only)
A8: U04 | B8: H2: actual minutes | C8: Peak | D8: =AVERAGE(c_acpk) -> 11.778261 | E8: =STDEV(c_acpk) -> 4.9265845 | F8: =COUNT(c_acpk) -> 276 | G8: Off-peak | H8: =AVERAGE(c_acop) -> 11.204919 | I8: =STDEV(c_acop) -> 3.347197 | J8: =COUNT(c_acop) -> 1179 | K8: =D8-H8 -> 0.57334145 | L8: =SQRT(E8^2/F8+I8^2/J8) -> 0.312157 | M8: =K8-1.96*L8 -> -0.038486279 | N8: =K8+1.96*L8 -> 1.1851692 | O8: =IF(OR(AND(M8>0,N8>0),AND(M8<0,N8<0)),"Clear: CI excludes 0","Not clear: CI includes 0") -> Not clear: CI includes 0 | P8: Calc_Orders ranges c_acpk and c_acop (delivered orders only)

Sheet Tests_Correlations
A1: Tests_Correlations: straight-line association (r) with 95% confidence intervals
A2: Method: Fisher z. z = FISHER(r); SE = 1/√(n − 3); CI = FISHERINV(z ± 1.96 × SE). r near 0 = no clear straight-line association, not proof of no relationship.
A4: ID | B4: Used for | C4: Measure X | D4: Measure Y | E4: Level | F4: n (pairs) | G4: r | H4: z = FISHER(r) | I4: SE = 1/√(n−3) | J4: 95% CI low (r) | K4: 95% CI high (r) | L4: Reading | M4: Formula for r
A5: R01 | B5: H4: store picking | C5: Store avg picking (min) | D5: Store late rate | E5: Store (20) | F5: =SUMPRODUCT(ISNUMBER(s_pick)*ISNUMBER(s_late_rate)) -> 20 | G5: =CORREL(s_pick,s_late_rate) -> 0.42604666 | H5: =FISHER(G5) -> 0.45505661 | I5: =1/SQRT(F5-3) -> 0.24253563 | J5: =FISHERINV(H5-1.96*I5) -> -0.020310425 | K5: =FISHERINV(H5+1.96*I5) -> 0.73079265 | L5: =IF(OR(AND(J5>0,K5>0),AND(J5<0,K5<0)),"Clear: CI excludes 0","No clear evidence: CI includes 0") -> No clear evidence: CI includes 0 | M5: =CORREL(s_pick,s_late_rate)
A6: R02 | B6: H4: staffing | C6: Staff per shift | D6: Store late rate | E6: Store (20) | F6: =SUMPRODUCT(ISNUMBER(s_staff)*ISNUMBER(s_late_rate)) -> 20 | G6: =CORREL(s_staff,s_late_rate) -> -0.064848528 | H6: =FISHER(G6) -> -0.064939661 | I6: =1/SQRT(F6-3) -> 0.24253563 | J6: =FISHERINV(H6-1.96*I6) -> -0.4932222 | K6: =FISHERINV(H6+1.96*I6) -> 0.38883787 | L6: =IF(OR(AND(J6>0,K6>0),AND(J6<0,K6<0)),"Clear: CI excludes 0","No clear evidence: CI includes 0") -> No clear evidence: CI includes 0 | M6: =CORREL(s_staff,s_late_rate)
A7: R03 | B7: H4: item availability | C7: Item availability | D7: Store late rate | E7: Store (20) | F7: =SUMPRODUCT(ISNUMBER(s_avail)*ISNUMBER(s_late_rate)) -> 20 | G7: =CORREL(s_avail,s_late_rate) -> 0.15808231 | H7: =FISHER(G7) -> 0.15941924 | I7: =1/SQRT(F7-3) -> 0.24253563 | J7: =FISHERINV(H7-1.96*I7) -> -0.30584085 | K7: =FISHERINV(H7+1.96*I7) -> 0.56134104 | L7: =IF(OR(AND(J7>0,K7>0),AND(J7<0,K7<0)),"Clear: CI excludes 0","No clear evidence: CI includes 0") -> No clear evidence: CI includes 0 | M7: =CORREL(s_avail,s_late_rate)
A8: R04 | B8: H6: store age | C8: Store age (days) | D8: Store late rate | E8: Store (20) | F8: =SUMPRODUCT(ISNUMBER(s_age)*ISNUMBER(s_late_rate)) -> 20 | G8: =CORREL(s_age,s_late_rate) -> 0.10863246 | H8: =FISHER(G8) -> 0.10906283 | I8: =1/SQRT(F8-3) -> 0.24253563 | J8: =FISHERINV(H8-1.96*I8) -> -0.35075726 | K8: =FISHERINV(H8+1.96*I8) -> 0.52587971 | L8: =IF(OR(AND(J8>0,K8>0),AND(J8<0,K8<0)),"Clear: CI excludes 0","No clear evidence: CI includes 0") -> No clear evidence: CI includes 0 | M8: =CORREL(s_age,s_late_rate)
A9: R05 | B9: H5: tickets | C9: Customer late share | D9: Support tickets | E9: Customer (250) | F9: =SUMPRODUCT(ISNUMBER(cu_late_share)*ISNUMBER(cu_tickets)) -> 250 | G9: =CORREL(cu_late_share,cu_tickets) -> 0.023125849 | H9: =FISHER(G9) -> 0.023129973 | I9: =1/SQRT(F9-3) -> 0.063628476 | J9: =FISHERINV(H9-1.96*I9) -> -0.10123387 | K9: =FISHERINV(H9+1.96*I9) -> 0.14677399 | L9: =IF(OR(AND(J9>0,K9>0),AND(J9<0,K9<0)),"Clear: CI excludes 0","No clear evidence: CI includes 0") -> No clear evidence: CI includes 0 | M9: =CORREL(cu_late_share,cu_tickets)
